Workbook

Sheet Оценки
A1: Фаза 1. Экспертные оценки важности критериев и альтернатив
A2: Шкала 1-10. Каждый эксперт даёт тройку: мин (наименьшее значение, которое он допускает), ожид (наиболее вероятное), макс (наибольшее).
A3: Для MIN-критериев (C2, C6) оценивается величина критерия: 10 - очень сложно или очень сильная зависимость.
A4: Ячейки на сером фоне - оценки экспертов. Если в тройке нарушен порядок мин <= ожид <= макс, она подсвечивается красным.
A6: 1. Важность критериев
A7: Код | B7: Критерий | C7: Тип | D7: E1 Колесникова А. А. | G7: E2 Пашинский П. В. | J7: E3 Степаненко А. И. | M7: E4 Кащенко А. В.
D8: мин | E8: ожид | F8: макс | G8: мин | H8: ожид | I8: макс | J8: мин | K8: ожид | L8: макс | M8: мин | N8: ожид | O8: макс
A9: C1 | B9: Ясность и формализуемость требований | C9: MAX | D9: 7 | E9: 8 | F9: 9 | G9: 6 | H9: 7 | I9: 9 | J9: 8 | K9: 9 | L9: 10 | M9: 6 | N9: 7 | O9: 8
A10: C2 | B10: Техническая сложность реализации | C10: MIN | D10: 5 | E10: 7 | F10: 8 | G10: 6 | H10: 8 | I10: 9 | J10: 5 | K10: 6 | L10: 7 | M10: 6 | N10: 7 | O10: 8
A11: C3 | B11: Знакомство команды с предметной областью | C11: MAX | D11: 5 | E11: 6 | F11: 7 | G11: 4 | H11: 5 | I11: 6 | J11: 6 | K11: 7 | L11: 8 | M11: 7 | N11: 8 | O11: 9
A12: C4 | B12: Практическая полезность | C12: MAX | D12: 4 | E12: 5 | F12: 6 | G12: 5 | H12: 6 | I12: 7 | J12: 3 | K12: 4 | L12: 6 | M12: 5 | N12: 6 | O12: 7
A13: C5 | B13: Разнообразие видов работ | C13: MAX | D13: 6 | E13: 7 | F13: 8 | G13: 5 | H13: 6 | I13: 8 | J13: 7 | K13: 8 | L13: 9 | M13: 6 | N13: 7 | O13: 8
A14: C6 | B14: Зависимость от внешних систем | C14: MIN | D14: 5 | E14: 6 | F14: 7 | G14: 6 | H14: 7 | I14: 8 | J14: 4 | K14: 5 | L14: 6 | M14: 7 | N14: 8 | O14: 9
A16: 2. Оценки альтернатив по критериям
A17: Код | B17: Альтернатива | C17: Тип | D17: E1 Колесникова А. А. | G17: E2 Пашинский П. В. | J17: E3 Степаненко А. И. | M17: E4 Кащенко А. В.
D18: мин | E18: ожид | F18: макс | G18: мин | H18: ожид | I18: макс | J18: мин | K18: ожид | L18: макс | M18: мин | N18: ожид | O18: макс
A19: C1. Ясность и формализуемость требований (MAX)
A20: A1 | B20: Управление системными службами | C20: MAX | D20: 7 | E20: 8 | F20: 9 | G20: 6 | H20: 7 | I20: 8 | J20: 7 | K20: 8 | L20: 9 | M20: 8 | N20: 9 | O20: 10
A21: A2 | B21: Мониторинг доступности | C21: MAX | D21: 7 | E21: 8 | F21: 9 | G21: 7 | H21: 8 | I21: 9 | J21: 6 | K21: 7 | L21: 9 | M21: 7 | N21: 8 | O21: 9
A22: A3 | B22: Контроль резервного копирования | C22: MAX | D22: 6 | E22: 7 | F22: 8 | G22: 6 | H22: 7 | I22: 8 | J22: 5 | K22: 6 | L22: 8 | M22: 6 | N22: 7 | O22: 8
A23: A4 | B23: Бот оповещений аудита | C23: MAX | D23: 5 | E23: 6 | F23: 7 | G23: 4 | H23: 5 | I23: 7 | J23: 5 | K23: 6 | L23: 7 | M23: 6 | N23: 7 | O23: 8
A24: C2. Техническая сложность реализации (MIN)
A25: A1 | B25: Управление системными службами | C25: MIN | D25: 6 | E25: 7 | F25: 8 | G25: 7 | H25: 8 | I25: 9 | J25: 6 | K25: 7 | L25: 9 | M25: 5 | N25: 6 | O25: 8
A26: A2 | B26: Мониторинг доступности | C26: MIN | D26: 4 | E26: 5 | F26: 6 | G26: 4 | H26: 5 | I26: 7 | J26: 5 | K26: 6 | L26: 7 | M26: 4 | N26: 5 | O26: 6
A27: A3 | B27: Контроль резервного копирования | C27: MIN | D27: 4 | E27: 5 | F27: 7 | G27: 4 | H27: 6 | I27: 7 | J27: 4 | K27: 5 | L27: 6 | M27: 5 | N27: 6 | O27: 7
A28: A4 | B28: Бот оповещений аудита | C28: MIN | D28: 5 | E28: 6 | F28: 7 | G28: 5 | H28: 6 | I28: 8 | J28: 4 | K28: 5 | L28: 7 | M28: 5 | N28: 6 | O28: 7
A29: C3. Знакомство команды с предметной областью (MAX)
A30: A1 | B30: Управление системными службами | C30: MAX | D30: 5 | E30: 6 | F30: 7 | G30: 5 | H30: 6 | I30: 8 | J30: 6 | K30: 7 | L30: 8 | M30: 8 | N30: 9 | O30: 10
A31: A2 | B31: Мониторинг доступности | C31: MAX | D31: 6 | E31: 7 | F31: 8 | G31: 6 | H31: 7 | I31: 8 | J31: 7 | K31: 8 | L31: 9 | M31: 6 | N31: 7 | O31: 8
A32: A3 | B32: Контроль резервного копирования | C32: MAX | D32: 4 | E32: 5 | F32: 6 | G32: 4 | H32: 5 | I32: 7 | J32: 5 | K32: 6 | L32: 7 | M32: 5 | N32: 6 | O32: 7
A33: A4 | B33: Бот оповещений аудита | C33: MAX | D33: 6 | E33: 7 | F33: 8 | G33: 5 | H33: 6 | I33: 7 | J33: 5 | K33: 6 | L33: 8 | M33: 6 | N33: 7 | O33: 8
A34: C4. Практическая полезность (MAX)
A35: A1 | B35: Управление системными службами | C35: MAX | D35: 6 | E35: 7 | F35: 8 | G35: 6 | H35: 7 | I35: 9 | J35: 5 | K35: 6 | L35: 8 | M35: 7 | N35: 8 | O35: 9
A36: A2 | B36: Мониторинг доступности | C36: MAX | D36: 7 | E36: 8 | F36: 9 | G36: 7 | H36: 8 | I36: 9 | J36: 6 | K36: 7 | L36: 8 | M36: 6 | N36: 7 | O36: 9
A37: A3 | B37: Контроль резервного копирования | C37: MAX | D37: 6 | E37: 7 | F37: 8 | G37: 7 | H37: 8 | I37: 9 | J37: 6 | K37: 7 | L37: 8 | M37: 6 | N37: 7 | O37: 8
A38: A4 | B38: Бот оповещений аудита | C38: MAX | D38: 5 | E38: 6 | F38: 7 | G38: 5 | H38: 6 | I38: 8 | J38: 6 | K38: 7 | L38: 8 | M38: 5 | N38: 6 | O38: 7
A39: C5. Разнообразие видов работ (MAX)
A40: A1 | B40: Управление системными службами | C40: MAX | D40: 6 | E40: 7 | F40: 8 | G40: 5 | H40: 7 | I40: 8 | J40: 6 | K40: 7 | L40: 9 | M40: 7 | N40: 8 | O40: 9
A41: A2 | B41: Мониторинг доступности | C41: MAX | D41: 7 | E41: 8 | F41: 9 | G41: 7 | H41: 8 | I41: 9 | J41: 6 | K41: 7 | L41: 8 | M41: 6 | N41: 7 | O41: 8
A42: A3 | B42: Контроль резервного копирования | C42: MAX | D42: 5 | E42: 6 | F42: 7 | G42: 5 | H42: 6 | I42: 8 | J42: 5 | K42: 6 | L42: 7 | M42: 5 | N42: 6 | O42: 7
...

Sheet TOPSIS
A1: Фаза 1. Нечёткий коллективный TOPSIS (метод Чена)
A2: Коллективная тройка: l = минимум из «мин» экспертов, m = среднее из «ожид», u = максимум из «макс». Веса делятся на 10, чтобы попасть в [0; 1].
A3: Нормализация: MAX - (l/u*, m/u*, u/u*), u* = наибольшее u по критерию; MIN - (l-/u, l-/m, l-/l), l- = наименьшее l по критерию.
A4: Взвешивание: покомпонентное умножение на нечёткий вес. FPIS = (1; 1; 1), FNIS = (0; 0; 0).
A5: d(a, b) = корень(1/3 * ((a1-b1)^2 + (a2-b2)^2 + (a3-b3)^2)). D+ и D- - суммы d по критериям, CC = D- / (D+ + D-).
A7: 1. Коллективные нечёткие веса критериев
A8: Код | B8: Критерий | C8: Тип | D8: Коллективная оценка | G8: Нечёткий вес
D9: l | E9: m | F9: u | G9: w_l | H9: w_m | I9: w_u
A10: C1 | B10: Ясность и формализуемость требований | C10: MAX | D10: =MIN(Оценки!D9,Оценки!G9,Оценки!J9,Оценки!M9) -> 6 | E10: =AVERAGE(Оценки!E9,Оценки!H9,Оценки!K9,Оценки!N9) -> 7.75 | F10: =MAX(Оценки!F9,Оценки!I9,Оценки!L9,Оценки!O9) -> 10 | G10: =D10/10 -> 0.6 | H10: =E10/10 -> 0.775 | I10: =F10/10 -> 1
A11: C2 | B11: Техническая сложность реализации | C11: MIN | D11: =MIN(Оценки!D10,Оценки!G10,Оценки!J10,Оценки!M10) -> 5 | E11: =AVERAGE(Оценки!E10,Оценки!H10,Оценки!K10,Оценки!N10) -> 7 | F11: =MAX(Оценки!F10,Оценки!I10,Оценки!L10,Оценки!O10) -> 9 | G11: =D11/10 -> 0.5 | H11: =E11/10 -> 0.7 | I11: =F11/10 -> 0.9
A12: C3 | B12: Знакомство команды с предметной областью | C12: MAX | D12: =MIN(Оценки!D11,Оценки!G11,Оценки!J11,Оценки!M11) -> 4 | E12: =AVERAGE(Оценки!E11,Оценки!H11,Оценки!K11,Оценки!N11) -> 6.5 | F12: =MAX(Оценки!F11,Оценки!I11,Оценки!L11,Оценки!O11) -> 9 | G12: =D12/10 -> 0.4 | H12: =E12/10 -> 0.65 | I12: =F12/10 -> 0.9
A13: C4 | B13: Практическая полезность | C13: MAX | D13: =MIN(Оценки!D12,Оценки!G12,Оценки!J12,Оценки!M12) -> 3 | E13: =AVERAGE(Оценки!E12,Оценки!H12,Оценки!K12,Оценки!N12) -> 5.25 | F13: =MAX(Оценки!F12,Оценки!I12,Оценки!L12,Оценки!O12) -> 7 | G13: =D13/10 -> 0.3 | H13: =E13/10 -> 0.525 | I13: =F13/10 -> 0.7
A14: C5 | B14: Разнообразие видов работ | C14: MAX | D14: =MIN(Оценки!D13,Оценки!G13,Оценки!J13,Оценки!M13) -> 5 | E14: =AVERAGE(Оценки!E13,Оценки!H13,Оценки!K13,Оценки!N13) -> 7 | F14: =MAX(Оценки!F13,Оценки!I13,Оценки!L13,Оценки!O13) -> 9 | G14: =D14/10 -> 0.5 | H14: =E14/10 -> 0.7 | I14: =F14/10 -> 0.9
A15: C6 | B15: Зависимость от внешних систем | C15: MIN | D15: =MIN(Оценки!D14,Оценки!G14,Оценки!J14,Оценки!M14) -> 4 | E15: =AVERAGE(Оценки!E14,Оценки!H14,Оценки!K14,Оценки!N14) -> 6.5 | F15: =MAX(Оценки!F14,Оценки!I14,Оценки!L14,Оценки!O14) -> 9 | G15: =D15/10 -> 0.4 | H15: =E15/10 -> 0.65 | I15: =F15/10 -> 0.9
A17: 2. Коллективные оценки, нормализация, взвешивание и расстояния
A18: Код | B18: Альтернатива | C18: Тип | D18: Коллективная оценка | G18: Нормализованная | J18: Взвешенная | M18: d+ | N18: d-
D19: l | E19: m | F19: u | G19: l | H19: m | I19: u | J19: l | K19: m | L19: u
A20: C1. Ясность и формализуемость требований (MAX) | G20: u* = | H20: =MAX(F21:F24) -> 10
A21: A1 | B21: Управление системными службами | C21: MAX | D21: =MIN(Оценки!D20,Оценки!G20,Оценки!J20,Оценки!M20) -> 6 | E21: =AVERAGE(Оценки!E20,Оценки!H20,Оценки!K20,Оценки!N20) -> 8 | F21: =MAX(Оценки!F20,Оценки!I20,Оценки!L20,Оценки!O20) -> 10 | G21: =D21/$H$20 -> 0.6 | H21: =E21/$H$20 -> 0.8 | I21: =F21/$H$20 -> 1 | J21: =G21*$G$10 -> 0.36 | K21: =H21*$H$10 -> 0.62 | L21: =I21*$I$10 -> 1 | M21: =SQRT(((1-J21)^2+(1-K21)^2+(1-L21)^2)/3) -> 0.4297286 | N21: =SQRT((J21^2+K21^2+L21^2)/3) -> 0.71039895
A22: A2 | B22: Мониторинг доступности | C22: MAX | D22: =MIN(Оценки!D21,Оценки!G21,Оценки!J21,Оценки!M21) -> 6 | E22: =AVERAGE(Оценки!E21,Оценки!H21,Оценки!K21,Оценки!N21) -> 7.75 | F22: =MAX(Оценки!F21,Оценки!I21,Оценки!L21,Оценки!O21) -> 9 | G22: =D22/$H$20 -> 0.6 | H22: =E22/$H$20 -> 0.775 | I22: =F22/$H$20 -> 0.9 | J22: =G22*$G$10 -> 0.36 | K22: =H22*$H$10 -> 0.600625 | L22: =I22*$I$10 -> 0.9 | M22: =SQRT(((1-J22)^2+(1-K22)^2+(1-L22)^2)/3) -> 0.43935574 | N22: =SQRT((J22^2+K22^2+L22^2)/3) -> 0.6583693
A23: A3 | B23: Контроль резервного копирования | C23: MAX | D23: =MIN(Оценки!D22,Оценки!G22,Оценки!J22,Оценки!M22) -> 5 | E23: =AVERAGE(Оценки!E22,Оценки!H22,Оценки!K22,Оценки!N22) -> 6.75 | F23: =MAX(Оценки!F22,Оценки!I22,Оценки!L22,Оценки!O22) -> 8 | G23: =D23/$H$20 -> 0.5 | H23: =E23/$H$20 -> 0.675 | I23: =F23/$H$20 -> 0.8 | J23: =G23*$G$10 -> 0.3 | K23: =H23*$H$10 -> 0.523125 | L23: =I23*$I$10 -> 0.8 | M23: =SQRT(((1-J23)^2+(1-K23)^2+(1-L23)^2)/3) -> 0.50246385 | N23: =SQRT((J23^2+K23^2+L23^2)/3) -> 0.57840579
A24: A4 | B24: Бот оповещений аудита | C24: MAX | D24: =MIN(Оценки!D23,Оценки!G23,Оценки!J23,Оценки!M23) -> 4 | E24: =AVERAGE(Оценки!E23,Оценки!H23,Оценки!K23,Оценки!N23) -> 6 | F24: =MAX(Оценки!F23,Оценки!I23,Оценки!L23,Оценки!O23) -> 8 | G24: =D24/$H$20 -> 0.4 | H24: =E24/$H$20 -> 0.6 | I24: =F24/$H$20 -> 0.8 | J24: =G24*$G$10 -> 0.24 | K24: =H24*$H$10 -> 0.465 | L24: =I24*$I$10 -> 0.8 | M24: =SQRT(((1-J24)^2+(1-K24)^2+(1-L24)^2)/3) -> 0.54888523 | N24: =SQRT((J24^2+K24^2+L24^2)/3) -> 0.55191334
A25: C2. Техническая сложность реализации (MIN) | G25: l- = | H25: =MIN(D26:D29) -> 4
A26: A1 | B26: Управление системными службами | C26: MIN | D26: =MIN(Оценки!D25,Оценки!G25,Оценки!J25,Оценки!M25) -> 5 | E26: =AVERAGE(Оценки!E25,Оценки!H25,Оценки!K25,Оценки!N25) -> 7 | F26: =MAX(Оценки!F25,Оценки!I25,Оценки!L25,Оценки!O25) -> 9 | G26: =$H$25/F26 -> 0.44444444 | H26: =$H$25/E26 -> 0.57142857 | I26: =$H$25/D26 -> 0.8 | J26: =G26*$G$11 -> 0.22222222 | K26: =H26*$H$11 -> 0.4 | L26: =I26*$I$11 -> 0.72 | M26: =SQRT(((1-J26)^2+(1-K26)^2+(1-L26)^2)/3) -> 0.58972826 | N26: =SQRT((J26^2+K26^2+L26^2)/3) -> 0.49253857
A27: A2 | B27: Мониторинг доступности | C27: MIN | D27: =MIN(Оценки!D26,Оценки!G26,Оценки!J26,Оценки!M26) -> 4 | E27: =AVERAGE(Оценки!E26,Оценки!H26,Оценки!K26,Оценки!N26) -> 5.25 | F27: =MAX(Оценки!F26,Оценки!I26,Оценки!L26,Оценки!O26) -> 7 | G27: =$H$25/F27 -> 0.57142857 | H27: =$H$25/E27 -> 0.76190476 | I27: =$H$25/D27 -> 1 | J27: =G27*$G$11 -> 0.28571429 | K27: =H27*$H$11 -> 0.53333333 | L27: =I27*$I$11 -> 0.9 | M27: =SQRT(((1-J27)^2+(1-K27)^2+(1-L27)^2)/3) -> 0.49597777 | N27: =SQRT((J27^2+K27^2+L27^2)/3) -> 0.62611956
A28: A3 | B28: Контроль резервного копирования | C28: MIN | D28: =MIN(Оценки!D27,Оценки!G27,Оценки!J27,Оценки!M27) -> 4 | E28: =AVERAGE(Оценки!E27,Оценки!H27,Оценки!K27,Оценки!N27) -> 5.5 | F28: =MAX(Оценки!F27,Оценки!I27,Оценки!L27,Оценки!O27) -> 7 | G28: =$H$25/F28 -> 0.57142857 | H28: =$H$25/E28 -> 0.72727273 | I28: =$H$25/D28 -> 1 | J28: =G28*$G$11 -> 0.28571429 | K28: =H28*$H$11 -> 0.50909091 | L28: =I28*$I$11 -> 0.9 | M28: =SQRT(((1-J28)^2+(1-K28)^2+(1-L28)^2)/3) -> 0.50371811 | N28: =SQRT((J28^2+K28^2+L28^2)/3) -> 0.61935617
A29: A4 | B29: Бот оповещений аудита | C29: MIN | D29: =MIN(Оценки!D28,Оценки!G28,Оценки!J28,Оценки!M28) -> 4 | E29: =AVERAGE(Оценки!E28,Оценки!H28,Оценки!K28,Оценки!N28) -> 5.75 | F29: =MAX(Оценки!F28,Оценки!I28,Оценки!L28,Оценки!O28) -> 8 | G29: =$H$25/F29 -> 0.5 | H29: =$H$25/E29 -> 0.69565217 | I29: =$H$25/D29 -> 1 | J29: =G29*$G$11 -> 0.25 | K29: =H29*$H$11 -> 0.48695652 | L29: =I29*$I$11 -> 0.9 | M29: =SQRT(((1-J29)^2+(1-K29)^2+(1-L29)^2)/3) -> 0.52779845 | N29: =SQRT((J29^2+K29^2+L29^2)/3) -> 0.60817395
A30: C3. Знакомство команды с предметной областью (MAX) | G30: u* = | H30: =MAX(F31:F34) -> 10
A31: A1 | B31: Управление системными службами | C31: MAX | D31: =MIN(Оценки!D30,Оценки!G30,Оценки!J30,Оценки!M30) -> 5 | E31: =AVERAGE(Оценки!E30,Оценки!H30,Оценки!K30,Оценки!N30) -> 7 | F31: =MAX(Оценки!F30,Оценки!I30,Оценки!L30,Оценки!O30) -> 10 | G31: =D31/$H$30 -> 0.5 | H31: =E31/$H$30 -> 0.7 | I31: =F31/$H$30 -> 1 | J31: =G31*$G$12 -> 0.2 | K31: =H31*$H$12 -> 0.455 | L31: =I31*$I$12 -> 0.9 | M31: =SQRT(((1-J31)^2+(1-K31)^2+(1-L31)^2)/3) -> 0.56184962 | N31: =SQRT((J31^2+K31^2+L31^2)/3) -> 0.59358375
A32: A2 | B32: Мониторинг доступности | C32: MAX | D32: =MIN(Оценки!D31,Оценки!G31,Оценки!J31,Оценки!M31) -> 6 | E32: =AVERAGE(Оценки!E31,Оценки!H31,Оценки!K31,Оценки!N31) -> 7.25 | F32: =MAX(Оценки!F31,Оценки!I31,Оценки!L31,Оценки!O31) -> 9 | G32: =D32/$H$30 -> 0.6 | H32: =E32/$H$30 -> 0.725 | I32: =F32/$H$30 -> 0.9 | J32: =G32*$G$12 -> 0.24 | K32: =H32*$H$12 -> 0.47125 | L32: =I32*$I$12 -> 0.81 | M32: =SQRT(((1-J32)^2+(1-K32)^2+(1-L32)^2)/3) -> 0.54567285 | N32: =SQRT((J32^2+K32^2+L32^2)/3) -> 0.55850293
A33: A3 | B33: Контроль резервного копирования | C33: MAX | D33: =MIN(Оценки!D32,Оценки!G32,Оценки!J32,Оценки!M32) -> 4 | E33: =AVERAGE(Оценки!E32,Оценки!H32,Оценки!K32,Оценки!N32) -> 5.5 | F33: =MAX(Оценки!F32,Оценки!I32,Оценки!L32,Оценки!O32) -> 7 | G33: =D33/$H$30 -> 0.4 | H33: =E33/$H$30 -> 0.55 | I33: =F33/$H$30 -> 0.7 | J33: =G33*$G$12 -> 0.16 | K33: =H33*$H$12 -> 0.3575 | L33: =I33*$I$12 -> 0.63 | M33: =SQRT(((1-J33)^2+(1-K33)^2+(1-L33)^2)/3) -> 0.64686584 | N33: =SQRT((J33^2+K33^2+L33^2)/3) -> 0.42829361
A34: A4 | B34: Бот оповещений аудита | C34: MAX | D34: =MIN(Оценки!D33,Оценки!G33,Оценки!J33,Оценки!M33) -> 5 | E34: =AVERAGE(Оценки!E33,Оценки!H33,Оценки!K33,Оценки!N33) -> 6.5 | F34: =MAX(Оценки!F33,Оценки!I33,Оценки!L33,Оценки!O33) -> 8 | G34: =D34/$H$30 -> 0.5 | H34: =E34/$H$30 -> 0.65 | I34: =F34/$H$30 -> 0.8 | J34: =G34*$G$12 -> 0.2 | K34: =H34*$H$12 -> 0.4225 | L34: =I34*$I$12 -> 0.72 | M34: =SQRT(((1-J34)^2+(1-K34)^2+(1-L34)^2)/3) -> 0.59214476 | N34: =SQRT((J34^2+K34^2+L34^2)/3) -> 0.4956162
A35: C4. Практическая полезность (MAX) | G35: u* = | H35: =MAX(F36:F39) -> 9
A36: A1 | B36: Управление системными службами | C36: MAX | D36: =MIN(Оценки!D35,Оценки!G35,Оценки!J35,Оценки!M35) -> 5 | E36: =AVERAGE(Оценки!E35,Оценки!H35,Оценки!K35,Оценки!N35) -> 7 | F36: =MAX(Оценки!F35,Оценки!I35,Оценки!L35,Оценки!O35) -> 9 | G36: =D36/$H$35 -> 0.55555556 | H36: =E36/$H$35 -> 0.77777778 | I36: =F36/$H$35 -> 1 | J36: =G36*$G$13 -> 0.16666667 | K36: =H36*$H$13 -> 0.40833333 | L36: =I36*$I$13 -> 0.7 | M36: =SQRT(((1-J36)^2+(1-K36)^2+(1-L36)^2)/3) -> 0.61495634 | N36: =SQRT((J36^2+K36^2+L36^2)/3) -> 0.47767279
A37: A2 | B37: Мониторинг доступности | C37: MAX | D37: =MIN(Оценки!D36,Оценки!G36,Оценки!J36,Оценки!M36) -> 6 | E37: =AVERAGE(Оценки!E36,Оценки!H36,Оценки!K36,Оценки!N36) -> 7.5 | F37: =MAX(Оценки!F36,Оценки!I36,Оценки!L36,Оценки!O36) -> 9 | G37: =D37/$H$35 -> 0.66666667 | H37: =E37/$H$35 -> 0.83333333 | I37: =F37/$H$35 -> 1 | J37: =G37*$G$13 -> 0.2 | K37: =H37*$H$13 -> 0.4375 | L37: =I37*$I$13 -> 0.7 | M37: =SQRT(((1-J37)^2+(1-K37)^2+(1-L37)^2)/3) -> 0.59059469 | N37: =SQRT((J37^2+K37^2+L37^2)/3) -> 0.49037613
A38: A3 | B38: Контроль резервного копирования | C38: MAX | D38: =MIN(Оценки!D37,Оценки!G37,Оценки!J37,Оценки!M37) -> 6 | E38: =AVERAGE(Оценки!E37,Оценки!H37,Оценки!K37,Оценки!N37) -> 7.25 | F38: =MAX(Оценки!F37,Оценки!I37,Оценки!L37,Оценки!O37) -> 9 | G38: =D38/$H$35 -> 0.66666667 | H38: =E38/$H$35 -> 0.80555556 | I38: =F38/$H$35 -> 1 | J38: =G38*$G$13 -> 0.2 | K38: =H38*$H$13 -> 0.42291667 | L38: =I38*$I$13 -> 0.7 | M38: =SQRT(((1-J38)^2+(1-K38)^2+(1-L38)^2)/3) -> 0.5952661 | N38: =SQRT((J38^2+K38^2+L38^2)/3) -> 0.48609276
A39: A4 | B39: Бот оповещений аудита | C39: MAX | D39: =MIN(Оценки!D38,Оценки!G38,Оценки!J38,Оценки!M38) -> 5 | E39: =AVERAGE(Оценки!E38,Оценки!H38,Оценки!K38,Оценки!N38) -> 6.25 | F39: =MAX(Оценки!F38,Оценки!I38,Оценки!L38,Оценки!O38) -> 8 | G39: =D39/$H$35 -> 0.55555556 | H39: =E39/$H$35 -> 0.69444444 | I39: =F39/$H$35 -> 0.88888889 | J39: =G39*$G$13 -> 0.16666667 | K39: =H39*$H$13 -> 0.36458333 | L39: =I39*$I$13 -> 0.62222222 | M39: =SQRT(((1-J39)^2+(1-K39)^2+(1-L39)^2)/3) -> 0.64314717 | N39: =SQRT((J39^2+K39^2+L39^2)/3) -> 0.42734033
A40: C5. Разнообразие видов работ (MAX) | G40: u* = | H40: =MAX(F41:F44) -> 9
A41: A1 | B41: Управление системными службами | C41: MAX | D41: =MIN(Оценки!D40,Оценки!G40,Оценки!J40,Оценки!M40) -> 5 | E41: =AVERAGE(Оценки!E40,Оценки!H40,Оценки!K40,Оценки!N40) -> 7.25 | F41: =MAX(Оценки!F40,Оценки!I40,Оценки!L40,Оценки!O40) -> 9 | G41: =D41/$H$40 -> 0.55555556 | H41: =E41/$H$40 -> 0.80555556 | I41: =F41/$H$40 -> 1 | J41: =G41*$G$14 -> 0.27777778 | K41: =H41*$H$14 -> 0.56388889 | L41: =I41*$I$14 -> 0.9 | M41: =SQRT(((1-J41)^2+(1-K41)^2+(1-L41)^2)/3) -> 0.4905092 | N41: =SQRT((J41^2+K41^2+L41^2)/3) -> 0.63380627
A42: A2 | B42: Мониторинг доступности | C42: MAX | D42: =MIN(Оценки!D41,Оценки!G41,Оценки!J41,Оценки!M41) -> 6 | E42: =AVERAGE(Оценки!E41,Оценки!H41,Оценки!K41,Оценки!N41) -> 7.5 | F42: =MAX(Оценки!F41,Оценки!I41,Оценки!L41,Оценки!O41) -> 9 | G42: =D42/$H$40 -> 0.66666667 | H42: =E42/$H$40 -> 0.83333333 | I42: =F42/$H$40 -> 1 | J42: =G42*$G$14 -> 0.33333333 | K42: =H42*$H$14 -> 0.58333333 | L42: =I42*$I$14 -> 0.9 | M42: =SQRT(((1-J42)^2+(1-K42)^2+(1-L42)^2)/3) -> 0.45754984 | N42: =SQRT((J42^2+K42^2+L42^2)/3) -> 0.64843116
...

Sheet МАИ оценки
A1: Фаза 1. Матрицы парных сравнений экспертов (шкала Саати 1-9)
A2: Заполняется только верхний треугольник (серые ячейки), дроби вводятся формулой: =1/3. Диагональ равна 1, нижний треугольник считается как 1/a(j,i).
A3: В строке i и столбце j: во сколько раз элемент строки важнее (лучше) элемента столбца. Для MIN-критериев лучше та концепция, у которой значение критерия меньше.
A4: w - веса по среднему геометрическому строк, λ = сумма по j (сумма столбца j * w_j), CR = (λ - n)/(n - 1)/RI, RI = 0.90 для n = 4 и 1.24 для n = 6.
A6: Эксперт E1: Колесникова А. А.
A7: Сравнение критериев по важности
B8: C1 | C8: C2 | D8: C3 | E8: C4 | F8: C5 | G8: C6 | H8: w
A9: C1 | B9: 1 | C9: 2 | D9: 3 | E9: 4 | F9: 2 | G9: 3 | H9: =GEOMEAN(B9:G9)/(GEOMEAN(B9:G9)+GEOMEAN(B10:G10)+GEOMEAN(B11:G11)+GEOMEAN(B12:G12)+GEOMEAN(B13:G13)+GEOMEAN(B14:G14)) -> 0.33151758
A10: C2 | B10: =1/C9 -> 0.5 | C10: 1 | D10: 2 | E10: 3 | F10: 1 | G10: 2 | H10: =GEOMEAN(B10:G10)/(GEOMEAN(B9:G9)+GEOMEAN(B10:G10)+GEOMEAN(B11:G11)+GEOMEAN(B12:G12)+GEOMEAN(B13:G13)+GEOMEAN(B14:G14)) -> 0.1951962
A11: C3 | B11: =1/D9 -> 0.33333333 | C11: =1/D10 -> 0.5 | D11: 1 | E11: 2 | F11: =1/2 -> 0.5 | G11: 1 | H11: =GEOMEAN(B11:G11)/(GEOMEAN(B9:G9)+GEOMEAN(B10:G10)+GEOMEAN(B11:G11)+GEOMEAN(B12:G12)+GEOMEAN(B13:G13)+GEOMEAN(B14:G14)) -> 0.10742061
A12: C4 | B12: =1/E9 -> 0.25 | C12: =1/E10 -> 0.33333333 | D12: =1/E11 -> 0.5 | E12: 1 | F12: =1/3 -> 0.33333333 | G12: =1/2 -> 0.5 | H12: =GEOMEAN(B12:G12)/(GEOMEAN(B9:G9)+GEOMEAN(B10:G10)+GEOMEAN(B11:G11)+GEOMEAN(B12:G12)+GEOMEAN(B13:G13)+GEOMEAN(B14:G14)) -> 0.063248815
A13: C5 | B13: =1/F9 -> 0.5 | C13: =1/F10 -> 1 | D13: =1/F11 -> 2 | E13: =1/F12 -> 3 | F13: 1 | G13: 2 | H13: =GEOMEAN(B13:G13)/(GEOMEAN(B9:G9)+GEOMEAN(B10:G10)+GEOMEAN(B11:G11)+GEOMEAN(B12:G12)+GEOMEAN(B13:G13)+GEOMEAN(B14:G14)) -> 0.1951962
A14: C6 | B14: =1/G9 -> 0.33333333 | C14: =1/G10 -> 0.5 | D14: =1/G11 -> 1 | E14: =1/G12 -> 2 | F14: =1/G13 -> 0.5 | G14: 1 | H14: =GEOMEAN(B14:G14)/(GEOMEAN(B9:G9)+GEOMEAN(B10:G10)+GEOMEAN(B11:G11)+GEOMEAN(B12:G12)+GEOMEAN(B13:G13)+GEOMEAN(B14:G14)) -> 0.10742061
A15: λ | B15: =SUM(B9:B14)*H9+SUM(C9:C14)*H10+SUM(D9:D14)*H11+SUM(E9:E14)*H12+SUM(F9:F14)*H13+SUM(G9:G14)*H14 -> 6.0387428 | C15: CR | D15: =(B15-6)/5/1.24 -> 0.006248838 | E15: =IF(D15<0.1,"согласована","пересмотреть") -> согласована
A17: C1. Ясность требований (MAX) | H17: C2. Сложность реализации (MIN) | O17: C3. Знакомство с областью (MAX)
B18: A1 | C18: A2 | D18: A3 | E18: A4 | F18: w | I18: A1 | J18: A2 | K18: A3 | L18: A4 | M18: w | P18: A1 | Q18: A2 | R18: A3 | S18: A4 | T18: w
A19: A1 | B19: 1 | C19: 1 | D19: 2 | E19: 3 | F19: =GEOMEAN(B19:E19)/(GEOMEAN(B19:E19)+GEOMEAN(B20:E20)+GEOMEAN(B21:E21)+GEOMEAN(B22:E22)) -> 0.3511869 | H19: A1 | I19: 1 | J19: =1/3 -> 0.33333333 | K19: =1/3 -> 0.33333333 | L19: =1/2 -> 0.5 | M19: =GEOMEAN(I19:L19)/(GEOMEAN(I19:L19)+GEOMEAN(I20:L20)+GEOMEAN(I21:L21)+GEOMEAN(I22:L22)) -> 0.10893875 | O19: A1 | P19: 1 | Q19: =1/2 -> 0.5 | R19: 2 | S19: =1/2 -> 0.5 | T19: =GEOMEAN(P19:S19)/(GEOMEAN(P19:S19)+GEOMEAN(P20:S20)+GEOMEAN(P21:S21)+GEOMEAN(P22:S22)) -> 0.18868744
A20: A2 | B20: =1/C19 -> 1 | C20: 1 | D20: 2 | E20: 3 | F20: =GEOMEAN(B20:E20)/(GEOMEAN(B19:E19)+GEOMEAN(B20:E20)+GEOMEAN(B21:E21)+GEOMEAN(B22:E22)) -> 0.3511869 | H20: A2 | I20: =1/J19 -> 3 | J20: 1 | K20: 1 | L20: 2 | M20: =GEOMEAN(I20:L20)/(GEOMEAN(I19:L19)+GEOMEAN(I20:L20)+GEOMEAN(I21:L21)+GEOMEAN(I22:L22)) -> 0.3511869 | O20: A2 | P20: =1/Q19 -> 2 | Q20: 1 | R20: 3 | S20: 1 | T20: =GEOMEAN(P20:S20)/(GEOMEAN(P19:S19)+GEOMEAN(P20:S20)+GEOMEAN(P21:S21)+GEOMEAN(P22:S22)) -> 0.3511869
A21: A3 | B21: =1/D19 -> 0.5 | C21: =1/D20 -> 0.5 | D21: 1 | E21: 2 | F21: =GEOMEAN(B21:E21)/(GEOMEAN(B19:E19)+GEOMEAN(B20:E20)+GEOMEAN(B21:E21)+GEOMEAN(B22:E22)) -> 0.18868744 | H21: A3 | I21: =1/K19 -> 3 | J21: =1/K20 -> 1 | K21: 1 | L21: 2 | M21: =GEOMEAN(I21:L21)/(GEOMEAN(I19:L19)+GEOMEAN(I20:L20)+GEOMEAN(I21:L21)+GEOMEAN(I22:L22)) -> 0.3511869 | O21: A3 | P21: =1/R19 -> 0.5 | Q21: =1/R20 -> 0.33333333 | R21: 1 | S21: =1/3 -> 0.33333333 | T21: =GEOMEAN(P21:S21)/(GEOMEAN(P19:S19)+GEOMEAN(P20:S20)+GEOMEAN(P21:S21)+GEOMEAN(P22:S22)) -> 0.10893875
A22: A4 | B22: =1/E19 -> 0.33333333 | C22: =1/E20 -> 0.33333333 | D22: =1/E21 -> 0.5 | E22: 1 | F22: =GEOMEAN(B22:E22)/(GEOMEAN(B19:E19)+GEOMEAN(B20:E20)+GEOMEAN(B21:E21)+GEOMEAN(B22:E22)) -> 0.10893875 | H22: A4 | I22: =1/L19 -> 2 | J22: =1/L20 -> 0.5 | K22: =1/L21 -> 0.5 | L22: 1 | M22: =GEOMEAN(I22:L22)/(GEOMEAN(I19:L19)+GEOMEAN(I20:L20)+GEOMEAN(I21:L21)+GEOMEAN(I22:L22)) -> 0.18868744 | O22: A4 | P22: =1/S19 -> 2 | Q22: =1/S20 -> 1 | R22: =1/S21 -> 3 | S22: 1 | T22: =GEOMEAN(P22:S22)/(GEOMEAN(P19:S19)+GEOMEAN(P20:S20)+GEOMEAN(P21:S21)+GEOMEAN(P22:S22)) -> 0.3511869
A23: λ | B23: =SUM(B19:B22)*F19+SUM(C19:C22)*F20+SUM(D19:D22)*F21+SUM(E19:E22)*F22 -> 4.0082888 | C23: CR | D23: =(B23-4)/3/0.9 -> 0.0030699217 | E23: =IF(D23<0.1,"согласована","пересмотреть") -> согласована | H23: λ | I23: =SUM(I19:I22)*M19+SUM(J19:J22)*M20+SUM(K19:K22)*M21+SUM(L19:L22)*M22 -> 4.0082888 | J23: CR | K23: =(I23-4)/3/0.9 -> 0.0030699217 | L23: =IF(K23<0.1,"согласована","пересмотреть") -> согласована | O23: λ | P23: =SUM(P19:P22)*T19+SUM(Q19:Q22)*T20+SUM(R19:R22)*T21+SUM(S19:S22)*T22 -> 4.0082888 | Q23: CR | R23: =(P23-4)/3/0.9 -> 0.0030699217 | S23: =IF(R23<0.1,"согласована","пересмотреть") -> согласована
A25: C4. Полезность (MAX) | H25: C5. Разнообразие работ (MAX) | O25: C6. Внешние зависимости (MIN)
B26: A1 | C26: A2 | D26: A3 | E26: A4 | F26: w | I26: A1 | J26: A2 | K26: A3 | L26: A4 | M26: w | P26: A1 | Q26: A2 | R26: A3 | S26: A4 | T26: w
A27: A1 | B27: 1 | C27: =1/2 -> 0.5 | D27: 1 | E27: 2 | F27: =GEOMEAN(B27:E27)/(GEOMEAN(B27:E27)+GEOMEAN(B28:E28)+GEOMEAN(B29:E29)+GEOMEAN(B30:E30)) -> 0.22735051 | H27: A1 | I27: 1 | J27: =1/2 -> 0.5 | K27: 2 | L27: 4 | M27: =GEOMEAN(I27:L27)/(GEOMEAN(I27:L27)+GEOMEAN(I28:L28)+GEOMEAN(I29:L29)+GEOMEAN(I30:L30)) -> 0.28542516 | O27: A1 | P27: 1 | Q27: 4 | R27: 1 | S27: 5 | T27: =GEOMEAN(P27:S27)/(GEOMEAN(P27:S27)+GEOMEAN(P28:S28)+GEOMEAN(P29:S29)+GEOMEAN(P30:S30)) -> 0.40666961
A28: A2 | B28: =1/C27 -> 2 | C28: 1 | D28: 2 | E28: 3 | F28: =GEOMEAN(B28:E28)/(GEOMEAN(B27:E27)+GEOMEAN(B28:E28)+GEOMEAN(B29:E29)+GEOMEAN(B30:E30)) -> 0.42314697 | H28: A2 | I28: =1/J27 -> 2 | J28: 1 | K28: 3 | L28: 5 | M28: =GEOMEAN(I28:L28)/(GEOMEAN(I27:L27)+GEOMEAN(I28:L28)+GEOMEAN(I29:L29)+GEOMEAN(I30:L30)) -> 0.47234309 | O28: A2 | P28: =1/Q27 -> 0.25 | Q28: 1 | R28: =1/4 -> 0.25 | S28: 2 | T28: =GEOMEAN(P28:S28)/(GEOMEAN(P27:S27)+GEOMEAN(P28:S28)+GEOMEAN(P29:S29)+GEOMEAN(P30:S30)) -> 0.11434356
A29: A3 | B29: =1/D27 -> 1 | C29: =1/D28 -> 0.5 | D29: 1 | E29: 2 | F29: =GEOMEAN(B29:E29)/(GEOMEAN(B27:E27)+GEOMEAN(B28:E28)+GEOMEAN(B29:E29)+GEOMEAN(B30:E30)) -> 0.22735051 | H29: A3 | I29: =1/K27 -> 0.5 | J29: =1/K28 -> 0.33333333 | K29: 1 | L29: 3 | M29: =GEOMEAN(I29:L29)/(GEOMEAN(I27:L27)+GEOMEAN(I28:L28)+GEOMEAN(I29:L29)+GEOMEAN(I30:L30)) -> 0.16971481 | O29: A3 | P29: =1/R27 -> 1 | Q29: =1/R28 -> 4 | R29: 1 | S29: 5 | T29: =GEOMEAN(P29:S29)/(GEOMEAN(P27:S27)+GEOMEAN(P28:S28)+GEOMEAN(P29:S29)+GEOMEAN(P30:S30)) -> 0.40666961
A30: A4 | B30: =1/E27 -> 0.5 | C30: =1/E28 -> 0.33333333 | D30: =1/E29 -> 0.5 | E30: 1 | F30: =GEOMEAN(B30:E30)/(GEOMEAN(B27:E27)+GEOMEAN(B28:E28)+GEOMEAN(B29:E29)+GEOMEAN(B30:E30)) -> 0.12215201 | H30: A4 | I30: =1/L27 -> 0.25 | J30: =1/L28 -> 0.2 | K30: =1/L29 -> 0.33333333 | L30: 1 | M30: =GEOMEAN(I30:L30)/(GEOMEAN(I27:L27)+GEOMEAN(I28:L28)+GEOMEAN(I29:L29)+GEOMEAN(I30:L30)) -> 0.072516935 | O30: A4 | P30: =1/S27 -> 0.2 | Q30: =1/S28 -> 0.5 | R30: =1/S29 -> 0.2 | S30: 1 | T30: =GEOMEAN(P30:S30)/(GEOMEAN(P27:S27)+GEOMEAN(P28:S28)+GEOMEAN(P29:S29)+GEOMEAN(P30:S30)) -> 0.072317219
A31: λ | B31: =SUM(B27:B30)*F27+SUM(C27:C30)*F28+SUM(D27:D30)*F29+SUM(E27:E30)*F30 -> 4.0107136 | C31: CR | D31: =(B31-4)/3/0.9 -> 0.0039679961 | E31: =IF(D31<0.1,"согласована","пересмотреть") -> согласована | H31: λ | I31: =SUM(I27:I30)*M27+SUM(J27:J30)*M28+SUM(K27:K30)*M29+SUM(L27:L30)*M30 -> 4.0483559 | J31: CR | K31: =(I31-4)/3/0.9 -> 0.017909611 | L31: =IF(K31<0.1,"согласована","пересмотреть") -> согласована | O31: λ | P31: =SUM(P27:P30)*T27+SUM(Q27:Q30)*T28+SUM(R27:R30)*T29+SUM(S27:S30)*T30 -> 4.0190688 | Q31: CR | R31: =(P31-4)/3/0.9 -> 0.0070625126 | S31: =IF(R31<0.1,"согласована","пересмотреть") -> согласована
A34: Эксперт E2: Пашинский П. В.
A35: Сравнение критериев по важности
B36: C1 | C36: C2 | D36: C3 | E36: C4 | F36: C5 | G36: C6 | H36: w
A37: C1 | B37: 1 | C37: =1/3 -> 0.33333333 | D37: 4 | E37: 3 | F37: 3 | G37: 1 | H37: =GEOMEAN(B37:G37)/(GEOMEAN(B37:G37)+GEOMEAN(B38:G38)+GEOMEAN(B39:G39)+GEOMEAN(B40:G40)+GEOMEAN(B41:G41)+GEOMEAN(B42:G42)) -> 0.19503142
A38: C2 | B38: =1/C37 -> 3 | C38: 1 | D38: 6 | E38: 4 | F38: 4 | G38: 3 | H38: =GEOMEAN(B38:G38)/(GEOMEAN(B37:G37)+GEOMEAN(B38:G38)+GEOMEAN(B39:G39)+GEOMEAN(B40:G40)+GEOMEAN(B41:G41)+GEOMEAN(B42:G42)) -> 0.39779561
A39: C3 | B39: =1/D37 -> 0.25 | C39: =1/D38 -> 0.16666667 | D39: 1 | E39: =1/3 -> 0.33333333 | F39: =1/3 -> 0.33333333 | G39: =1/4 -> 0.25 | H39: =GEOMEAN(B39:G39)/(GEOMEAN(B37:G37)+GEOMEAN(B38:G38)+GEOMEAN(B39:G39)+GEOMEAN(B40:G40)+GEOMEAN(B41:G41)+GEOMEAN(B42:G42)) -> 0.041765922
A40: C4 | B40: =1/E37 -> 0.33333333 | C40: =1/E38 -> 0.25 | D40: =1/E39 -> 3 | E40: 1 | F40: 1 | G40: =1/3 -> 0.33333333 | H40: =GEOMEAN(B40:G40)/(GEOMEAN(B37:G37)+GEOMEAN(B38:G38)+GEOMEAN(B39:G39)+GEOMEAN(B40:G40)+GEOMEAN(B41:G41)+GEOMEAN(B42:G42)) -> 0.085187817
A41: C5 | B41: =1/F37 -> 0.33333333 | C41: =1/F38 -> 0.25 | D41: =1/F39 -> 3 | E41: =1/F40 -> 1 | F41: 1 | G41: =1/3 -> 0.33333333 | H41: =GEOMEAN(B41:G41)/(GEOMEAN(B37:G37)+GEOMEAN(B38:G38)+GEOMEAN(B39:G39)+GEOMEAN(B40:G40)+GEOMEAN(B41:G41)+GEOMEAN(B42:G42)) -> 0.085187817
A42: C6 | B42: =1/G37 -> 1 | C42: =1/G38 -> 0.33333333 | D42: =1/G39 -> 4 | E42: =1/G40 -> 3 | F42: =1/G41 -> 3 | G42: 1 | H42: =GEOMEAN(B42:G42)/(GEOMEAN(B37:G37)+GEOMEAN(B38:G38)+GEOMEAN(B39:G39)+GEOMEAN(B40:G40)+GEOMEAN(B41:G41)+GEOMEAN(B42:G42)) -> 0.19503142
A43: λ | B43: =SUM(B37:B42)*H37+SUM(C37:C42)*H38+SUM(D37:D42)*H39+SUM(E37:E42)*H40+SUM(F37:F42)*H41+SUM(G37:G42)*H42 -> 6.2144454 | C43: CR | D43: =(B43-6)/5/1.24 -> 0.034587963 | E43: =IF(D43<0.1,"согласована","пересмотреть") -> согласована
A45: C1. Ясность требований (MAX) | H45: C2. Сложность реализации (MIN) | O45: C3. Знакомство с областью (MAX)
B46: A1 | C46: A2 | D46: A3 | E46: A4 | F46: w | I46: A1 | J46: A2 | K46: A3 | L46: A4 | M46: w | P46: A1 | Q46: A2 | R46: A3 | S46: A4 | T46: w
...

Sheet МАИ
A1: Фаза 1. Чёткий коллективный МАИ
A2: Матрицы экспертов объединяются поэлементным средним геометрическим. Веса и CR считаются так же, как на листе «МАИ оценки».
A3: Глобальный приоритет альтернативы = сумма по критериям (вес критерия * локальный приоритет альтернативы по этому критерию).
A5: 1. Согласованность матриц экспертов (CR)
A6: Эксперт | C6: Критерии | E6: C1 | F6: C2 | G6: C3 | H6: C4 | I6: C5 | J6: C6
A7: E1 | C7: ='МАИ оценки'!D15 -> 0.006248838 | E7: ='МАИ оценки'!D23 -> 0.0030699217 | F7: ='МАИ оценки'!K23 -> 0.0030699217 | G7: ='МАИ оценки'!R23 -> 0.0030699217 | H7: ='МАИ оценки'!D31 -> 0.0039679961 | I7: ='МАИ оценки'!K31 -> 0.017909611 | J7: ='МАИ оценки'!R31 -> 0.0070625126
A8: E2 | C8: ='МАИ оценки'!D43 -> 0.034587963 | E8: ='МАИ оценки'!D51 -> 0.023397375 | F8: ='МАИ оценки'!K51 -> 0.023397375 | G8: ='МАИ оценки'!R51 -> 0.032121418 | H8: ='МАИ оценки'!D59 -> 0.022753188 | I8: ='МАИ оценки'!K59 -> 0.066888004 | J8: ='МАИ оценки'!R59 -> 0.075483719
A9: E3 | C9: ='МАИ оценки'!D71 -> 0.020266082 | E9: ='МАИ оценки'!D79 -> 0.0046977912 | F9: ='МАИ оценки'!K79 -> 0.0030699217 | G9: ='МАИ оценки'!R79 -> 0.0046977912 | H9: ='МАИ оценки'!D87 -> 3.2895497e-16 | I9: ='МАИ оценки'!K87 -> 0.0079792323 | J9: ='МАИ оценки'!R87 -> 0.018004915
A10: E4 | C10: ='МАИ оценки'!D99 -> 0.0081046373 | E10: ='МАИ оценки'!D107 -> 0.021383112 | F10: ='МАИ оценки'!K107 -> 0 | G10: ='МАИ оценки'!R107 -> 0.030900996 | H10: ='МАИ оценки'!D115 -> 0.017123992 | I10: ='МАИ оценки'!K115 -> 0.059496129 | J10: ='МАИ оценки'!R115 -> 0.021340655
A11: Матриц с CR >= 0.1: | G11: =COUNTIF(C7:K10,">=0.1") -> 0
A13: 2. Агрегированные матрицы (среднее геометрическое по экспертам)
A14: Сравнение критериев по важности
B15: C1 | C15: C2 | D15: C3 | E15: C4 | F15: C5 | G15: C6 | H15: w
A16: C1 | B16: =GEOMEAN('МАИ оценки'!B9,'МАИ оценки'!B37,'МАИ оценки'!B65,'МАИ оценки'!B93) -> 1 | C16: =GEOMEAN('МАИ оценки'!C9,'МАИ оценки'!C37,'МАИ оценки'!C65,'МАИ оценки'!C93) -> 1.2778862 | D16: =GEOMEAN('МАИ оценки'!D9,'МАИ оценки'!D37,'МАИ оценки'!D65,'МАИ оценки'!D93) -> 1.8612097 | E16: =GEOMEAN('МАИ оценки'!E9,'МАИ оценки'!E37,'МАИ оценки'!E65,'МАИ оценки'!E93) -> 3.8336586 | F16: =GEOMEAN('МАИ оценки'!F9,'МАИ оценки'!F37,'МАИ оценки'!F65,'МАИ оценки'!F93) -> 1.8612097 | G16: =GEOMEAN('МАИ оценки'!G9,'МАИ оценки'!G37,'МАИ оценки'!G65,'МАИ оценки'!G93) -> 1.4953488 | H16: =GEOMEAN(B16:G16)/(GEOMEAN(B16:G16)+GEOMEAN(B17:G17)+GEOMEAN(B18:G18)+GEOMEAN(B19:G19)+GEOMEAN(B20:G20)+GEOMEAN(B21:G21)) -> 0.26364309
A17: C2 | B17: =GEOMEAN('МАИ оценки'!B10,'МАИ оценки'!B38,'МАИ оценки'!B66,'МАИ оценки'!B94) -> 0.78254229 | C17: =GEOMEAN('МАИ оценки'!C10,'МАИ оценки'!C38,'МАИ оценки'!C66,'МАИ оценки'!C94) -> 1 | D17: =GEOMEAN('МАИ оценки'!D10,'МАИ оценки'!D38,'МАИ оценки'!D66,'МАИ оценки'!D94) -> 1.1892071 | E17: =GEOMEAN('МАИ оценки'!E10,'МАИ оценки'!E38,'МАИ оценки'!E66,'МАИ оценки'!E94) -> 3.2237098 | F17: =GEOMEAN('МАИ оценки'!F10,'МАИ оценки'!F38,'МАИ оценки'!F66,'МАИ оценки'!F94) -> 1.0745699 | G17: =GEOMEAN('МАИ оценки'!G10,'МАИ оценки'!G38,'МАИ оценки'!G66,'МАИ оценки'!G94) -> 1.4142136 | H17: =GEOMEAN(B17:G17)/(GEOMEAN(B16:G16)+GEOMEAN(B17:G17)+GEOMEAN(B18:G18)+GEOMEAN(B19:G19)+GEOMEAN(B20:G20)+GEOMEAN(B21:G21)) -> 0.19804099
A18: C3 | B18: =GEOMEAN('МАИ оценки'!B11,'МАИ оценки'!B39,'МАИ оценки'!B67,'МАИ оценки'!B95) -> 0.53728497 | C18: =GEOMEAN('МАИ оценки'!C11,'МАИ оценки'!C39,'МАИ оценки'!C67,'МАИ оценки'!C95) -> 0.84089642 | D18: =GEOMEAN('МАИ оценки'!D11,'МАИ оценки'!D39,'МАИ оценки'!D67,'МАИ оценки'!D95) -> 1 | E18: =GEOMEAN('МАИ оценки'!E11,'МАИ оценки'!E39,'МАИ оценки'!E67,'МАИ оценки'!E95) -> 1.9108856 | F18: =GEOMEAN('МАИ оценки'!F11,'МАИ оценки'!F39,'МАИ оценки'!F67,'МАИ оценки'!F95) -> 0.70710678 | G18: =GEOMEAN('МАИ оценки'!G11,'МАИ оценки'!G39,'МАИ оценки'!G67,'МАИ оценки'!G95) -> 0.93060486 | H18: =GEOMEAN(B18:G18)/(GEOMEAN(B16:G16)+GEOMEAN(B17:G17)+GEOMEAN(B18:G18)+GEOMEAN(B19:G19)+GEOMEAN(B20:G20)+GEOMEAN(B21:G21)) -> 0.13996366
A19: C4 | B19: =GEOMEAN('МАИ оценки'!B12,'МАИ оценки'!B40,'МАИ оценки'!B68,'МАИ оценки'!B96) -> 0.26084743 | C19: =GEOMEAN('МАИ оценки'!C12,'МАИ оценки'!C40,'МАИ оценки'!C68,'МАИ оценки'!C96) -> 0.31020162 | D19: =GEOMEAN('МАИ оценки'!D12,'МАИ оценки'!D40,'МАИ оценки'!D68,'МАИ оценки'!D96) -> 0.52331757 | E19: =GEOMEAN('МАИ оценки'!E12,'МАИ оценки'!E40,'МАИ оценки'!E68,'МАИ оценки'!E96) -> 1 | F19: =GEOMEAN('МАИ оценки'!F12,'МАИ оценки'!F40,'МАИ оценки'!F68,'МАИ оценки'!F96) -> 0.3860974 | G19: =GEOMEAN('МАИ оценки'!G12,'МАИ оценки'!G40,'МАИ оценки'!G68,'МАИ оценки'!G96) -> 0.35930411 | H19: =GEOMEAN(B19:G19)/(GEOMEAN(B16:G16)+GEOMEAN(B17:G17)+GEOMEAN(B18:G18)+GEOMEAN(B19:G19)+GEOMEAN(B20:G20)+GEOMEAN(B21:G21)) -> 0.065328461
A20: C5 | B20: =GEOMEAN('МАИ оценки'!B13,'МАИ оценки'!B41,'МАИ оценки'!B69,'МАИ оценки'!B97) -> 0.53728497 | C20: =GEOMEAN('МАИ оценки'!C13,'МАИ оценки'!C41,'МАИ оценки'!C69,'МАИ оценки'!C97) -> 0.93060486 | D20: =GEOMEAN('МАИ оценки'!D13,'МАИ оценки'!D41,'МАИ оценки'!D69,'МАИ оценки'!D97) -> 1.4142136 | E20: =GEOMEAN('МАИ оценки'!E13,'МАИ оценки'!E41,'МАИ оценки'!E69,'МАИ оценки'!E97) -> 2.5900201 | F20: =GEOMEAN('МАИ оценки'!F13,'МАИ оценки'!F41,'МАИ оценки'!F69,'МАИ оценки'!F97) -> 1 | G20: =GEOMEAN('МАИ оценки'!G13,'МАИ оценки'!G41,'МАИ оценки'!G69,'МАИ оценки'!G97) -> 0.97098354 | H20: =GEOMEAN(B20:G20)/(GEOMEAN(B16:G16)+GEOMEAN(B17:G17)+GEOMEAN(B18:G18)+GEOMEAN(B19:G19)+GEOMEAN(B20:G20)+GEOMEAN(B21:G21)) -> 0.16928167
A21: C6 | B21: =GEOMEAN('МАИ оценки'!B14,'МАИ оценки'!B42,'МАИ оценки'!B70,'МАИ оценки'!B98) -> 0.6687403 | C21: =GEOMEAN('МАИ оценки'!C14,'МАИ оценки'!C42,'МАИ оценки'!C70,'МАИ оценки'!C98) -> 0.70710678 | D21: =GEOMEAN('МАИ оценки'!D14,'МАИ оценки'!D42,'МАИ оценки'!D70,'МАИ оценки'!D98) -> 1.0745699 | E21: =GEOMEAN('МАИ оценки'!E14,'МАИ оценки'!E42,'МАИ оценки'!E70,'МАИ оценки'!E98) -> 2.7831577 | F21: =GEOMEAN('МАИ оценки'!F14,'МАИ оценки'!F42,'МАИ оценки'!F70,'МАИ оценки'!F98) -> 1.0298836 | G21: =GEOMEAN('МАИ оценки'!G14,'МАИ оценки'!G42,'МАИ оценки'!G70,'МАИ оценки'!G98) -> 1 | H21: =GEOMEAN(B21:G21)/(GEOMEAN(B16:G16)+GEOMEAN(B17:G17)+GEOMEAN(B18:G18)+GEOMEAN(B19:G19)+GEOMEAN(B20:G20)+GEOMEAN(B21:G21)) -> 0.16374214
A22: λ | B22: =SUM(B16:B21)*H16+SUM(C16:C21)*H17+SUM(D16:D21)*H18+SUM(E16:E21)*H19+SUM(F16:F21)*H20+SUM(G16:G21)*H21 -> 6.0284973 | C22: CR | D22: =(B22-6)/5/1.24 -> 0.0045963464 | E22: =IF(D22<0.1,"согласована","пересмотреть") -> согласована
A24: C1. Ясность требований (MAX) | H24: C2. Сложность реализации (MIN) | O24: C3. Знакомство с областью (MAX)
B25: A1 | C25: A2 | D25: A3 | E25: A4 | F25: w | I25: A1 | J25: A2 | K25: A3 | L25: A4 | M25: w | P25: A1 | Q25: A2 | R25: A3 | S25: A4 | T25: w
A26: A1 | B26: =GEOMEAN('МАИ оценки'!B19,'МАИ оценки'!B47,'МАИ оценки'!B75,'МАИ оценки'!B103) -> 1 | C26: =GEOMEAN('МАИ оценки'!C19,'МАИ оценки'!C47,'МАИ оценки'!C75,'МАИ оценки'!C103) -> 1.1892071 | D26: =GEOMEAN('МАИ оценки'!D19,'МАИ оценки'!D47,'МАИ оценки'!D75,'МАИ оценки'!D103) -> 2.3403473 | E26: =GEOMEAN('МАИ оценки'!E19,'МАИ оценки'!E47,'МАИ оценки'!E75,'МАИ оценки'!E103) -> 3.6628415 | F26: =GEOMEAN(B26:E26)/(GEOMEAN(B26:E26)+GEOMEAN(B27:E27)+GEOMEAN(B28:E28)+GEOMEAN(B29:E29)) -> 0.3882964 | H26: A1 | I26: =GEOMEAN('МАИ оценки'!I19,'МАИ оценки'!I47,'МАИ оценки'!I75,'МАИ оценки'!I103) -> 1 | J26: =GEOMEAN('МАИ оценки'!J19,'МАИ оценки'!J47,'МАИ оценки'!J75,'МАИ оценки'!J103) -> 0.31020162 | K26: =GEOMEAN('МАИ оценки'!K19,'МАИ оценки'!K47,'МАИ оценки'!K75,'МАИ оценки'!K103) -> 0.40824829 | L26: =GEOMEAN('МАИ оценки'!L19,'МАИ оценки'!L47,'МАИ оценки'!L75,'МАИ оценки'!L103) -> 0.451801 | M26: =GEOMEAN(I26:L26)/(GEOMEAN(I26:L26)+GEOMEAN(I27:L27)+GEOMEAN(I28:L28)+GEOMEAN(I29:L29)) -> 0.11153101 | O26: A1 | P26: =GEOMEAN('МАИ оценки'!P19,'МАИ оценки'!P47,'МАИ оценки'!P75,'МАИ оценки'!P103) -> 1 | Q26: =GEOMEAN('МАИ оценки'!Q19,'МАИ оценки'!Q47,'МАИ оценки'!Q75,'МАИ оценки'!Q103) -> 0.80342842 | R26: =GEOMEAN('МАИ оценки'!R19,'МАИ оценки'!R47,'МАИ оценки'!R75,'МАИ оценки'!R103) -> 3.0274001 | S26: =GEOMEAN('МАИ оценки'!S19,'МАИ оценки'!S47,'МАИ оценки'!S75,'МАИ оценки'!S103) -> 1.4953488 | T26: =GEOMEAN(P26:S26)/(GEOMEAN(P26:S26)+GEOMEAN(P27:S27)+GEOMEAN(P28:S28)+GEOMEAN(P29:S29)) -> 0.31147765
A27: A2 | B27: =GEOMEAN('МАИ оценки'!B20,'МАИ оценки'!B48,'МАИ оценки'!B76,'МАИ оценки'!B104) -> 0.84089642 | C27: =GEOMEAN('МАИ оценки'!C20,'МАИ оценки'!C48,'МАИ оценки'!C76,'МАИ оценки'!C104) -> 1 | D27: =GEOMEAN('МАИ оценки'!D20,'МАИ оценки'!D48,'МАИ оценки'!D76,'МАИ оценки'!D104) -> 2.4494897 | E27: =GEOMEAN('МАИ оценки'!E20,'МАИ оценки'!E48,'МАИ оценки'!E76,'МАИ оценки'!E104) -> 3.2237098 | F27: =GEOMEAN(B27:E27)/(GEOMEAN(B26:E26)+GEOMEAN(B27:E27)+GEOMEAN(B28:E28)+GEOMEAN(B29:E29)) -> 0.34883327 | H27: A2 | I27: =GEOMEAN('МАИ оценки'!I20,'МАИ оценки'!I48,'МАИ оценки'!I76,'МАИ оценки'!I104) -> 3.2237098 | J27: =GEOMEAN('МАИ оценки'!J20,'МАИ оценки'!J48,'МАИ оценки'!J76,'МАИ оценки'!J104) -> 1 | K27: =GEOMEAN('МАИ оценки'!K20,'МАИ оценки'!K48,'МАИ оценки'!K76,'МАИ оценки'!K104) -> 1.4564753 | L27: =GEOMEAN('МАИ оценки'!L20,'МАИ оценки'!L48,'МАИ оценки'!L76,'МАИ оценки'!L104) -> 1.7320508 | M27: =GEOMEAN(I27:L27)/(GEOMEAN(I26:L26)+GEOMEAN(I27:L27)+GEOMEAN(I28:L28)+GEOMEAN(I29:L29)) -> 0.38509834 | O27: A2 | P27: =GEOMEAN('МАИ оценки'!P20,'МАИ оценки'!P48,'МАИ оценки'!P76,'МАИ оценки'!P104) -> 1.244666 | Q27: =GEOMEAN('МАИ оценки'!Q20,'МАИ оценки'!Q48,'МАИ оценки'!Q76,'МАИ оценки'!Q104) -> 1 | R27: =GEOMEAN('МАИ оценки'!R20,'МАИ оценки'!R48,'МАИ оценки'!R76,'МАИ оценки'!R104) -> 3.2237098 | S27: =GEOMEAN('МАИ оценки'!S20,'МАИ оценки'!S48,'МАИ оценки'!S76,'МАИ оценки'!S104) -> 1.7320508 | T27: =GEOMEAN(P27:S27)/(GEOMEAN(P26:S26)+GEOMEAN(P27:S27)+GEOMEAN(P28:S28)+GEOMEAN(P29:S29)) -> 0.36620928
A28: A3 | B28: =GEOMEAN('МАИ оценки'!B21,'МАИ оценки'!B49,'МАИ оценки'!B77,'МАИ оценки'!B105) -> 0.42728701 | C28: =GEOMEAN('МАИ оценки'!C21,'МАИ оценки'!C49,'МАИ оценки'!C77,'МАИ оценки'!C105) -> 0.40824829 | D28: =GEOMEAN('МАИ оценки'!D21,'МАИ оценки'!D49,'МАИ оценки'!D77,'МАИ оценки'!D105) -> 1 | E28: =GEOMEAN('МАИ оценки'!E21,'МАИ оценки'!E49,'МАИ оценки'!E77,'МАИ оценки'!E105) -> 1.6817928 | F28: =GEOMEAN(B28:E28)/(GEOMEAN(B26:E26)+GEOMEAN(B27:E27)+GEOMEAN(B28:E28)+GEOMEAN(B29:E29)) -> 0.15992948 | H28: A3 | I28: =GEOMEAN('МАИ оценки'!I21,'МАИ оценки'!I49,'МАИ оценки'!I77,'МАИ оценки'!I105) -> 2.4494897 | J28: =GEOMEAN('МАИ оценки'!J21,'МАИ оценки'!J49,'МАИ оценки'!J77,'МАИ оценки'!J105) -> 0.68658905 | K28: =GEOMEAN('МАИ оценки'!K21,'МАИ оценки'!K49,'МАИ оценки'!K77,'МАИ оценки'!K105) -> 1 | L28: =GEOMEAN('МАИ оценки'!L21,'МАИ оценки'!L49,'МАИ оценки'!L77,'МАИ оценки'!L105) -> 1.1892071 | M28: =GEOMEAN(I28:L28)/(GEOMEAN(I26:L26)+GEOMEAN(I27:L27)+GEOMEAN(I28:L28)+GEOMEAN(I29:L29)) -> 0.27119034 | O28: A3 | P28: =GEOMEAN('МАИ оценки'!P21,'МАИ оценки'!P49,'МАИ оценки'!P77,'МАИ оценки'!P105) -> 0.33031643 | Q28: =GEOMEAN('МАИ оценки'!Q21,'МАИ оценки'!Q49,'МАИ оценки'!Q77,'МАИ оценки'!Q105) -> 0.31020162 | R28: =GEOMEAN('МАИ оценки'!R21,'МАИ оценки'!R49,'МАИ оценки'!R77,'МАИ оценки'!R105) -> 1 | S28: =GEOMEAN('МАИ оценки'!S21,'МАИ оценки'!S49,'МАИ оценки'!S77,'МАИ оценки'!S105) -> 0.43869134 | T28: =GEOMEAN(P28:S28)/(GEOMEAN(P26:S26)+GEOMEAN(P27:S27)+GEOMEAN(P28:S28)+GEOMEAN(P29:S29)) -> 0.10385331
A29: A4 | B29: =GEOMEAN('МАИ оценки'!B22,'МАИ оценки'!B50,'МАИ оценки'!B78,'МАИ оценки'!B106) -> 0.27301209 | C29: =GEOMEAN('МАИ оценки'!C22,'МАИ оценки'!C50,'МАИ оценки'!C78,'МАИ оценки'!C106) -> 0.31020162 | D29: =GEOMEAN('МАИ оценки'!D22,'МАИ оценки'!D50,'МАИ оценки'!D78,'МАИ оценки'!D106) -> 0.59460356 | E29: =GEOMEAN('МАИ оценки'!E22,'МАИ оценки'!E50,'МАИ оценки'!E78,'МАИ оценки'!E106) -> 1 | F29: =GEOMEAN(B29:E29)/(GEOMEAN(B26:E26)+GEOMEAN(B27:E27)+GEOMEAN(B28:E28)+GEOMEAN(B29:E29)) -> 0.10294085 | H29: A4 | I29: =GEOMEAN('МАИ оценки'!I22,'МАИ оценки'!I50,'МАИ оценки'!I78,'МАИ оценки'!I106) -> 2.2133638 | J29: =GEOMEAN('МАИ оценки'!J22,'МАИ оценки'!J50,'МАИ оценки'!J78,'МАИ оценки'!J106) -> 0.57735027 | K29: =GEOMEAN('МАИ оценки'!K22,'МАИ оценки'!K50,'МАИ оценки'!K78,'МАИ оценки'!K106) -> 0.84089642 | L29: =GEOMEAN('МАИ оценки'!L22,'МАИ оценки'!L50,'МАИ оценки'!L78,'МАИ оценки'!L106) -> 1 | M29: =GEOMEAN(I29:L29)/(GEOMEAN(I26:L26)+GEOMEAN(I27:L27)+GEOMEAN(I28:L28)+GEOMEAN(I29:L29)) -> 0.23218031 | O29: A4 | P29: =GEOMEAN('МАИ оценки'!P22,'МАИ оценки'!P50,'МАИ оценки'!P78,'МАИ оценки'!P106) -> 0.6687403 | Q29: =GEOMEAN('МАИ оценки'!Q22,'МАИ оценки'!Q50,'МАИ оценки'!Q78,'МАИ оценки'!Q106) -> 0.57735027 | R29: =GEOMEAN('МАИ оценки'!R22,'МАИ оценки'!R50,'МАИ оценки'!R78,'МАИ оценки'!R106) -> 2.2795071 | S29: =GEOMEAN('МАИ оценки'!S22,'МАИ оценки'!S50,'МАИ оценки'!S78,'МАИ оценки'!S106) -> 1 | T29: =GEOMEAN(P29:S29)/(GEOMEAN(P26:S26)+GEOMEAN(P27:S27)+GEOMEAN(P28:S28)+GEOMEAN(P29:S29)) -> 0.21845976
A30: λ | B30: =SUM(B26:B29)*F26+SUM(C26:C29)*F27+SUM(D26:D29)*F28+SUM(E26:E29)*F29 -> 4.0070583 | C30: CR | D30: =(B30-4)/3/0.9 -> 0.0026141868 | E30: =IF(D30<0.1,"согласована","пересмотреть") -> согласована | H30: λ | I30: =SUM(I26:I29)*M26+SUM(J26:J29)*M27+SUM(K26:K29)*M28+SUM(L26:L29)*M29 -> 4.0026913 | J30: CR | K30: =(I30-4)/3/0.9 -> 0.00099678285 | L30: =IF(K30<0.1,"согласована","пересмотреть") -> согласована | O30: λ | P30: =SUM(P26:P29)*T26+SUM(Q26:Q29)*T27+SUM(R26:R29)*T28+SUM(S26:S29)*T29 -> 4.0049483 | Q30: CR | R30: =(P30-4)/3/0.9 -> 0.001832699 | S30: =IF(R30<0.1,"согласована","пересмотреть") -> согласована
A32: C4. Полезность (MAX) | H32: C5. Разнообразие работ (MAX) | O32: C6. Внешние зависимости (MIN)
B33: A1 | C33: A2 | D33: A3 | E33: A4 | F33: w | I33: A1 | J33: A2 | K33: A3 | L33: A4 | M33: w | P33: A1 | Q33: A2 | R33: A3 | S33: A4 | T33: w
A34: A1 | B34: =GEOMEAN('МАИ оценки'!B27,'МАИ оценки'!B55,'МАИ оценки'!B83,'МАИ оценки'!B111) -> 1 | C34: =GEOMEAN('МАИ оценки'!C27,'МАИ оценки'!C55,'МАИ оценки'!C83,'МАИ оценки'!C111) -> 0.70710678 | D34: =GEOMEAN('МАИ оценки'!D27,'МАИ оценки'!D55,'МАИ оценки'!D83,'МАИ оценки'!D111) -> 0.84089642 | E34: =GEOMEAN('МАИ оценки'!E27,'МАИ оценки'!E55,'МАИ оценки'!E83,'МАИ оценки'!E111) -> 1.9679897 | F34: =GEOMEAN(B34:E34)/(GEOMEAN(B34:E34)+GEOMEAN(B35:E35)+GEOMEAN(B36:E36)+GEOMEAN(B37:E37)) -> 0.24542901 | H34: A1 | I34: =GEOMEAN('МАИ оценки'!I27,'МАИ оценки'!I55,'МАИ оценки'!I83,'МАИ оценки'!I111) -> 1 | J34: =GEOMEAN('МАИ оценки'!J27,'МАИ оценки'!J55,'МАИ оценки'!J83,'МАИ оценки'!J111) -> 0.84089642 | K34: =GEOMEAN('МАИ оценки'!K27,'МАИ оценки'!K55,'МАИ оценки'!K83,'МАИ оценки'!K111) -> 2.7831577 | L34: =GEOMEAN('МАИ оценки'!L27,'МАИ оценки'!L55,'МАИ оценки'!L83,'МАИ оценки'!L111) -> 5.7326568 | M34: =GEOMEAN(I34:L34)/(GEOMEAN(I34:L34)+GEOMEAN(I35:L35)+GEOMEAN(I36:L36)+GEOMEAN(I37:L37)) -> 0.37015174 | O34: A1 | P34: =GEOMEAN('МАИ оценки'!P27,'МАИ оценки'!P55,'МАИ оценки'!P83,'МАИ оценки'!P111) -> 1 | Q34: =GEOMEAN('МАИ оценки'!Q27,'МАИ оценки'!Q55,'МАИ оценки'!Q83,'МАИ оценки'!Q111) -> 4.5270191 | R34: =GEOMEAN('МАИ оценки'!R27,'МАИ оценки'!R55,'МАИ оценки'!R83,'МАИ оценки'!R111) -> 1.316074 | S34: =GEOMEAN('МАИ оценки'!S27,'МАИ оценки'!S55,'МАИ оценки'!S83,'МАИ оценки'!S111) -> 6.3442276 | T34: =GEOMEAN(P34:S34)/(GEOMEAN(P34:S34)+GEOMEAN(P35:S35)+GEOMEAN(P36:S36)+GEOMEAN(P37:S37)) -> 0.45034531
A35: A2 | B35: =GEOMEAN('МАИ оценки'!B28,'МАИ оценки'!B56,'МАИ оценки'!B84,'МАИ оценки'!B112) -> 1.4142136 | C35: =GEOMEAN('МАИ оценки'!C28,'МАИ оценки'!C56,'МАИ оценки'!C84,'МАИ оценки'!C112) -> 1 | D35: =GEOMEAN('МАИ оценки'!D28,'МАИ оценки'!D56,'МАИ оценки'!D84,'МАИ оценки'!D112) -> 1.1892071 | E35: =GEOMEAN('МАИ оценки'!E28,'МАИ оценки'!E56,'МАИ оценки'!E84,'МАИ оценки'!E112) -> 2.4494897 | F35: =GEOMEAN(B35:E35)/(GEOMEAN(B34:E34)+GEOMEAN(B35:E35)+GEOMEAN(B36:E36)+GEOMEAN(B37:E37)) -> 0.33618269 | H35: A2 | I35: =GEOMEAN('МАИ оценки'!I28,'МАИ оценки'!I56,'МАИ оценки'!I84,'МАИ оценки'!I112) -> 1.1892071 | J35: =GEOMEAN('МАИ оценки'!J28,'МАИ оценки'!J56,'МАИ оценки'!J84,'МАИ оценки'!J112) -> 1 | K35: =GEOMEAN('МАИ оценки'!K28,'МАИ оценки'!K56,'МАИ оценки'!K84,'МАИ оценки'!K112) -> 2.9129506 | L35: =GEOMEAN('МАИ оценки'!L28,'МАИ оценки'!L56,'МАИ оценки'!L84,'МАИ оценки'!L112) -> 5.9160798 | M35: =GEOMEAN(I35:L35)/(GEOMEAN(I34:L34)+GEOMEAN(I35:L35)+GEOMEAN(I36:L36)+GEOMEAN(I37:L37)) -> 0.41150668 | O35: A2 | P35: =GEOMEAN('МАИ оценки'!P28,'МАИ оценки'!P56,'МАИ оценки'!P84,'МАИ оценки'!P112) -> 0.22089591 | Q35: =GEOMEAN('МАИ оценки'!Q28,'МАИ оценки'!Q56,'МАИ оценки'!Q84,'МАИ оценки'!Q112) -> 1 | R35: =GEOMEAN('МАИ оценки'!R28,'МАИ оценки'!R56,'МАИ оценки'!R84,'МАИ оценки'!R112) -> 0.2259005 | S35: =GEOMEAN('МАИ оценки'!S28,'МАИ оценки'!S56,'МАИ оценки'!S84,'МАИ оценки'!S112) -> 2.4494897 | T35: =GEOMEAN(P35:S35)/(GEOMEAN(P34:S34)+GEOMEAN(P35:S35)+GEOMEAN(P36:S36)+GEOMEAN(P37:S37)) -> 0.10739225
A36: A3 | B36: =GEOMEAN('МАИ оценки'!B29,'МАИ оценки'!B57,'МАИ оценки'!B85,'МАИ оценки'!B113) -> 1.1892071 | C36: =GEOMEAN('МАИ оценки'!C29,'МАИ оценки'!C57,'МАИ оценки'!C85,'МАИ оценки'!C113) -> 0.84089642 | D36: =GEOMEAN('МАИ оценки'!D29,'МАИ оценки'!D57,'МАИ оценки'!D85,'МАИ оценки'!D113) -> 1 | E36: =GEOMEAN('МАИ оценки'!E29,'МАИ оценки'!E57,'МАИ оценки'!E85,'МАИ оценки'!E113) -> 2.2133638 | F36: =GEOMEAN(B36:E36)/(GEOMEAN(B34:E34)+GEOMEAN(B35:E35)+GEOMEAN(B36:E36)+GEOMEAN(B37:E37)) -> 0.28782368 | H36: A3 | I36: =GEOMEAN('МАИ оценки'!I29,'МАИ оценки'!I57,'МАИ оценки'!I85,'МАИ оценки'!I113) -> 0.35930411 | J36: =GEOMEAN('МАИ оценки'!J29,'МАИ оценки'!J57,'МАИ оценки'!J85,'МАИ оценки'!J113) -> 0.34329452 | K36: =GEOMEAN('МАИ оценки'!K29,'МАИ оценки'!K57,'МАИ оценки'!K85,'МАИ оценки'!K113) -> 1 | L36: =GEOMEAN('МАИ оценки'!L29,'МАИ оценки'!L57,'МАИ оценки'!L85,'МАИ оценки'!L113) -> 3.9359793 | M36: =GEOMEAN(I36:L36)/(GEOMEAN(I34:L34)+GEOMEAN(I35:L35)+GEOMEAN(I36:L36)+GEOMEAN(I37:L37)) -> 0.16144188 | O36: A3 | P36: =GEOMEAN('МАИ оценки'!P29,'МАИ оценки'!P57,'МАИ оценки'!P85,'МАИ оценки'!P113) -> 0.75983569 | Q36: =GEOMEAN('МАИ оценки'!Q29,'МАИ оценки'!Q57,'МАИ оценки'!Q85,'МАИ оценки'!Q113) -> 4.4267277 | R36: =GEOMEAN('МАИ оценки'!R29,'МАИ оценки'!R57,'МАИ оценки'!R85,'МАИ оценки'!R113) -> 1 | S36: =GEOMEAN('МАИ оценки'!S29,'МАИ оценки'!S57,'МАИ оценки'!S85,'МАИ оценки'!S113) -> 5.9160798 | T36: =GEOMEAN(P36:S36)/(GEOMEAN(P34:S34)+GEOMEAN(P35:S35)+GEOMEAN(P36:S36)+GEOMEAN(P37:S37)) -> 0.38360736
A37: A4 | B37: =GEOMEAN('МАИ оценки'!B30,'МАИ оценки'!B58,'МАИ оценки'!B86,'МАИ оценки'!B114) -> 0.50813275 | C37: =GEOMEAN('МАИ оценки'!C30,'МАИ оценки'!C58,'МАИ оценки'!C86,'МАИ оценки'!C114) -> 0.40824829 | D37: =GEOMEAN('МАИ оценки'!D30,'МАИ оценки'!D58,'МАИ оценки'!D86,'МАИ оценки'!D114) -> 0.451801 | E37: =GEOMEAN('МАИ оценки'!E30,'МАИ оценки'!E58,'МАИ оценки'!E86,'МАИ оценки'!E114) -> 1 | F37: =GEOMEAN(B37:E37)/(GEOMEAN(B34:E34)+GEOMEAN(B35:E35)+GEOMEAN(B36:E36)+GEOMEAN(B37:E37)) -> 0.13056462 | H37: A4 | I37: =GEOMEAN('МАИ оценки'!I30,'МАИ оценки'!I58,'МАИ оценки'!I86,'МАИ оценки'!I114) -> 0.17443919 | J37: =GEOMEAN('МАИ оценки'!J30,'МАИ оценки'!J58,'МАИ оценки'!J86,'МАИ оценки'!J114) -> 0.16903085 | K37: =GEOMEAN('МАИ оценки'!K30,'МАИ оценки'!K58,'МАИ оценки'!K86,'МАИ оценки'!K114) -> 0.25406637 | L37: =GEOMEAN('МАИ оценки'!L30,'МАИ оценки'!L58,'МАИ оценки'!L86,'МАИ оценки'!L114) -> 1 | M37: =GEOMEAN(I37:L37)/(GEOMEAN(I34:L34)+GEOMEAN(I35:L35)+GEOMEAN(I36:L36)+GEOMEAN(I37:L37)) -> 0.056899708 | O37: A4 | P37: =GEOMEAN('МАИ оценки'!P30,'МАИ оценки'!P58,'МАИ оценки'!P86,'МАИ оценки'!P114) -> 0.1576236 | Q37: =GEOMEAN('МАИ оценки'!Q30,'МАИ оценки'!Q58,'МАИ оценки'!Q86,'МАИ оценки'!Q114) -> 0.40824829 | R37: =GEOMEAN('МАИ оценки'!R30,'МАИ оценки'!R58,'МАИ оценки'!R86,'МАИ оценки'!R114) -> 0.16903085 | S37: =GEOMEAN('МАИ оценки'!S30,'МАИ оценки'!S58,'МАИ оценки'!S86,'МАИ оценки'!S114) -> 1 | T37: =GEOMEAN(P37:S37)/(GEOMEAN(P34:S34)+GEOMEAN(P35:S35)+GEOMEAN(P36:S36)+GEOMEAN(P37:S37)) -> 0.058655089
A38: λ | B38: =SUM(B34:B37)*F34+SUM(C34:C37)*F35+SUM(D34:D37)*F36+SUM(E34:E37)*F37 -> 4.0014278 | C38: CR | D38: =(B38-4)/3/0.9 -> 0.00052880942 | E38: =IF(D38<0.1,"согласована","пересмотреть") -> согласована | H38: λ | I38: =SUM(I34:I37)*M34+SUM(J34:J37)*M35+SUM(K34:K37)*M36+SUM(L34:L37)*M37 -> 4.041986 | J38: CR | K38: =(I38-4)/3/0.9 -> 0.015550384 | L38: =IF(K38<0.1,"согласована","пересмотреть") -> согласована | O38: λ | P38: =SUM(P34:P37)*T34+SUM(Q34:Q37)*T35+SUM(R34:R37)*T36+SUM(S34:S37)*T37 -> 4.0372173 | Q38: CR | R38: =(P38-4)/3/0.9 -> 0.013784181 | S38: =IF(R38<0.1,"согласована","пересмотреть") -> согласована
A41: 3. Глобальные приоритеты
A42: Код | B42: C1 | C42: C2 | D42: C3 | E42: C4 | F42: C5 | G42: C6 | H42: Приоритет | I42: Ранг | J42: Концепция
A43: w | B43: =H16 -> 0.26364309 | C43: =H17 -> 0.19804099 | D43: =H18 -> 0.13996366 | E43: =H19 -> 0.065328461 | F43: =H20 -> 0.16928167 | G43: =H21 -> 0.16374214
A44: A1 | B44: =F26 -> 0.3882964 | C44: =M26 -> 0.11153101 | D44: =T26 -> 0.31147765 | E44: =F34 -> 0.24542901 | F44: =M34 -> 0.37015174 | G44: =T34 -> 0.45034531 | H44: =SUMPRODUCT(B44:G44,$B$43:$G$43) -> 0.32048883 | I44: =RANK(H44,$H$44:$H$47,0) -> 2 | J44: Управление системными службами
A45: A2 | B45: =F27 -> 0.34883327 | C45: =M27 -> 0.38509834 | D45: =T27 -> 0.36620928 | E45: =F35 -> 0.33618269 | F45: =M35 -> 0.41150668 | G45: =T35 -> 0.10739225 | H45: =SUMPRODUCT(B45:G45,$B$43:$G$43) -> 0.3286962 | I45: =RANK(H45,$H$44:$H$47,0) -> 1 | J45: Мониторинг доступности
A46: A3 | B46: =F28 -> 0.15992948 | C46: =M28 -> 0.27119034 | D46: =T28 -> 0.10385331 | E46: =F36 -> 0.28782368 | F46: =M36 -> 0.16144188 | G46: =T36 -> 0.38360736 | H46: =SUMPRODUCT(B46:G46,$B$43:$G$43) -> 0.21935171 | I46: =RANK(H46,$H$44:$H$47,0) -> 3 | J46: Контроль резервного копирования
...

Sheet Итог
A1: Фаза 1. Сравнение результатов TOPSIS и МАИ
A2: Значения берутся с листов «TOPSIS» и «МАИ». Коэффициент Спирмена: rho = 1 - 6 * сумма(d^2) / (n * (n^2 - 1)), d - разница рангов.
A4: 1. Ранжирование двумя методами
A5: Код | B5: Концепция | F5: CC TOPSIS | G5: Ранг | H5: Приоритет МАИ | I5: Ранг | J5: Разница
A6: A1 | B6: Управление системными службами | F6: =TOPSIS!F53 -> 0.50422167 | G6: =TOPSIS!G53 -> 1 | H6: =МАИ!H44 -> 0.32048883 | I6: =МАИ!I44 -> 2 | J6: =G6-I6 -> -1
A7: A2 | B7: Мониторинг доступности | F7: =TOPSIS!F54 -> 0.47592427 | G7: =TOPSIS!G54 -> 2 | H7: =МАИ!H45 -> 0.3286962 | I7: =МАИ!I45 -> 1 | J7: =G7-I7 -> 1
A8: A3 | B8: Контроль резервного копирования | F8: =TOPSIS!F55 -> 0.45444475 | G8: =TOPSIS!G55 -> 3 | H8: =МАИ!H46 -> 0.21935171 | I8: =МАИ!I46 -> 3 | J8: =G8-I8 -> 0
A9: A4 | B9: Бот оповещений аудита | F9: =TOPSIS!F56 -> 0.39693086 | G9: =TOPSIS!G56 -> 4 | H9: =МАИ!H47 -> 0.13146326 | I9: =МАИ!I47 -> 4 | J9: =G9-I9 -> 0
A11: Коэффициент Спирмена: | F11: =1-6*SUMSQ(J6:J9)/(4*(4^2-1)) -> 0.8
A13: 2. Устойчивость МАИ к весам критериев (локальные приоритеты не меняются)
A14: Набор весов | D14: C1 | E14: C2 | F14: C3 | G14: C4 | H14: C5 | I14: C6 | J14: A1 | K14: A2 | L14: A3 | M14: A4 | N14: Лидер
A15: Веса МАИ (базовые) | D15: =МАИ!B43 -> 0.26364309 | E15: =МАИ!C43 -> 0.19804099 | F15: =МАИ!D43 -> 0.13996366 | G15: =МАИ!E43 -> 0.065328461 | H15: =МАИ!F43 -> 0.16928167 | I15: =МАИ!G43 -> 0.16374214 | J15: =SUMPRODUCT($D15:$I15,МАИ!$B$44:$G$44)/SUM($D15:$I15) -> 0.32048883 | K15: =SUMPRODUCT($D15:$I15,МАИ!$B$45:$G$45)/SUM($D15:$I15) -> 0.3286962 | L15: =SUMPRODUCT($D15:$I15,МАИ!$B$46:$G$46)/SUM($D15:$I15) -> 0.21935171 | M15: =SUMPRODUCT($D15:$I15,МАИ!$B$47:$G$47)/SUM($D15:$I15) -> 0.13146326 | N15: =INDEX($J$14:$M$14,MATCH(MAX(J15:M15),J15:M15,0)) -> A2
A16: Веса TOPSIS (m) | D16: =TOPSIS!H10 -> 0.775 | E16: =TOPSIS!H11 -> 0.7 | F16: =TOPSIS!H12 -> 0.65 | G16: =TOPSIS!H13 -> 0.525 | H16: =TOPSIS!H14 -> 0.7 | I16: =TOPSIS!H15 -> 0.65 | J16: =SUMPRODUCT($D16:$I16,МАИ!$B$44:$G$44)/SUM($D16:$I16) -> 0.3155357 | K16: =SUMPRODUCT($D16:$I16,МАИ!$B$45:$G$45)/SUM($D16:$I16) -> 0.32807655 | L16: =SUMPRODUCT($D16:$I16,МАИ!$B$46:$G$46)/SUM($D16:$I16) -> 0.22368619 | M16: =SUMPRODUCT($D16:$I16,МАИ!$B$47:$G$47)/SUM($D16:$I16) -> 0.13270156 | N16: =INDEX($J$14:$M$14,MATCH(MAX(J16:M16),J16:M16,0)) -> A2
A17: Равные веса | D17: =1 -> 1 | E17: =1 -> 1 | F17: =1 -> 1 | G17: =1 -> 1 | H17: =1 -> 1 | I17: =1 -> 1 | J17: =SUMPRODUCT($D17:$I17,МАИ!$B$44:$G$44)/SUM($D17:$I17) -> 0.31287185 | K17: =SUMPRODUCT($D17:$I17,МАИ!$B$45:$G$45)/SUM($D17:$I17) -> 0.32587042 | L17: =SUMPRODUCT($D17:$I17,МАИ!$B$46:$G$46)/SUM($D17:$I17) -> 0.22797434 | M17: =SUMPRODUCT($D17:$I17,МАИ!$B$47:$G$47)/SUM($D17:$I17) -> 0.13328339 | N17: =INDEX($J$14:$M$14,MATCH(MAX(J17:M17),J17:M17,0)) -> A2
A18: Вес C2 x 0.8 | D18: =МАИ!B43 -> 0.26364309 | E18: =МАИ!C43*0.8 -> 0.15843279 | F18: =МАИ!D43 -> 0.13996366 | G18: =МАИ!E43 -> 0.065328461 | H18: =МАИ!F43 -> 0.16928167 | I18: =МАИ!G43 -> 0.16374214 | J18: =SUMPRODUCT($D18:$I18,МАИ!$B$44:$G$44)/SUM($D18:$I18) -> 0.32910661 | K18: =SUMPRODUCT($D18:$I18,МАИ!$B$45:$G$45)/SUM($D18:$I18) -> 0.32637008 | L18: =SUMPRODUCT($D18:$I18,МАИ!$B$46:$G$46)/SUM($D18:$I18) -> 0.2172138 | M18: =SUMPRODUCT($D18:$I18,МАИ!$B$47:$G$47)/SUM($D18:$I18) -> 0.12730952 | N18: =INDEX($J$14:$M$14,MATCH(MAX(J18:M18),J18:M18,0)) -> A1
A19: Вес C2 x 1.2 | D19: =МАИ!B43 -> 0.26364309 | E19: =МАИ!C43*1.2 -> 0.23764919 | F19: =МАИ!D43 -> 0.13996366 | G19: =МАИ!E43 -> 0.065328461 | H19: =МАИ!F43 -> 0.16928167 | I19: =МАИ!G43 -> 0.16374214 | J19: =SUMPRODUCT($D19:$I19,МАИ!$B$44:$G$44)/SUM($D19:$I19) -> 0.31252771 | K19: =SUMPRODUCT($D19:$I19,МАИ!$B$45:$G$45)/SUM($D19:$I19) -> 0.33084507 | L19: =SUMPRODUCT($D19:$I19,МАИ!$B$46:$G$46)/SUM($D19:$I19) -> 0.22132672 | M19: =SUMPRODUCT($D19:$I19,МАИ!$B$47:$G$47)/SUM($D19:$I19) -> 0.1353005 | N19: =INDEX($J$14:$M$14,MATCH(MAX(J19:M19),J19:M19,0)) -> A2
A20: Вес C6 x 0.8 | D20: =МАИ!B43 -> 0.26364309 | E20: =МАИ!C43 -> 0.19804099 | F20: =МАИ!D43 -> 0.13996366 | G20: =МАИ!E43 -> 0.065328461 | H20: =МАИ!F43 -> 0.16928167 | I20: =МАИ!G43*0.8 -> 0.13099371 | J20: =SUMPRODUCT($D20:$I20,МАИ!$B$44:$G$44)/SUM($D20:$I20) -> 0.31609225 | K20: =SUMPRODUCT($D20:$I20,МАИ!$B$45:$G$45)/SUM($D20:$I20) -> 0.33618893 | L20: =SUMPRODUCT($D20:$I20,МАИ!$B$46:$G$46)/SUM($D20:$I20) -> 0.21379047 | M20: =SUMPRODUCT($D20:$I20,МАИ!$B$47:$G$47)/SUM($D20:$I20) -> 0.13392834 | N20: =INDEX($J$14:$M$14,MATCH(MAX(J20:M20),J20:M20,0)) -> A2
A21: Вес C6 x 1.2 | D21: =МАИ!B43 -> 0.26364309 | E21: =МАИ!C43 -> 0.19804099 | F21: =МАИ!D43 -> 0.13996366 | G21: =МАИ!E43 -> 0.065328461 | H21: =МАИ!F43 -> 0.16928167 | I21: =МАИ!G43*1.2 -> 0.19649056 | J21: =SUMPRODUCT($D21:$I21,МАИ!$B$44:$G$44)/SUM($D21:$I21) -> 0.32460658 | K21: =SUMPRODUCT($D21:$I21,МАИ!$B$45:$G$45)/SUM($D21:$I21) -> 0.32167865 | L21: =SUMPRODUCT($D21:$I21,МАИ!$B$46:$G$46)/SUM($D21:$I21) -> 0.22456025 | M21: =SUMPRODUCT($D21:$I21,МАИ!$B$47:$G$47)/SUM($D21:$I21) -> 0.12915452 | N21: =INDEX($J$14:$M$14,MATCH(MAX(J21:M21),J21:M21,0)) -> A1
A23: Выбранная концепция: | F23: A1. Сервис управления системными службами серверов
